<?xml version="1.0"?>
<robot name="robocam">

    <!-- Robot Links -->
    <link name="base">
        <visual>
            <geometry>
                <cylinder length=".07" radius="0.03"/>
            </geometry>
            <origin xyz="0 0 .0325" rpy="0 0 0" />
        </visual>

        <collision>
            <geometry>
                <cylinder length=".07" radius="0.03"/>
            </geometry>
            <origin xyz="0 0 .0325" rpy="0 0 0" />
        </collision>
    </link>

    <link name="link_rot">
        <visual>
            <geometry>
                <cylinder length=".07" radius="0.03"/>
            </geometry>
            <origin xyz="0 0 .03" rpy="0 0 0" />
            <material name='blue'>
                <color rgba="0 0 0.8 1"/>
            </material>
        </visual>

        <inertial>
            <origin xyz="0 0 .03" rpy="0 0 0"/> <mass value=".6" />
            <inertia ixx=".001" ixy="0" ixz="0" iyy=".001" iyz="0" izz=".001" />
        </inertial>

        <collision>
            <geometry>
                <cylinder length=".07" radius="0.03"/>
            </geometry>
            <origin xyz="0 0 .03" rpy="0 0 0" />
        </collision>
    </link>
    
    <link name="link_1">
        <visual>
            <geometry>
                <cylinder length=".336" radius="0.005"/>
            </geometry>
            <origin xyz="0 0 .1685" rpy="0 0 0" />
        </visual>
        
        <inertial>
            <origin xyz="0 0 .1685" rpy="0 0 0"/>
            <mass value="1.5" />
            <inertia ixx=".001" ixy="0" ixz="0" iyy=".001" iyz="0" izz=".001" />
        </inertial>

        <collision>
            <geometry>
                <cylinder length=".336" radius="0.005"/>
            </geometry>
            <origin xyz="0 0 .1685" rpy="0 0 0" />
        </collision>
    </link>

    <link name="link_1_mimic">
        <visual>
            <geometry>
                <cylinder length=".336" radius="0.005"/>
            </geometry>
            <origin xyz="0 0 .1685" rpy="0 0 0" />
            <material name='yellow'>
                <color rgba="0.9 0.9 0 1"/>
            </material>
        </visual>
        
        <inertial>
            <origin xyz="0 0 .1685" rpy="0 0 0"/>
            <mass value="1.5" />
            <inertia ixx=".001" ixy="0" ixz="0" iyy=".001" iyz="0" izz=".001" />
        </inertial>

        <collision>
            <geometry>
                <cylinder length=".336" radius="0.005"/>
            </geometry>
            <origin xyz="0 0 .171" rpy="0 0 0" />
        </collision>
    </link>

    <link name="link_f1">
        <visual>
            <geometry>
                <cylinder length=".06" radius="0.039"/>
            </geometry>
            <origin xyz="0 0 .03" rpy="0 0 0" />
            <material name='black'>
                <color rgba="0 0 0 1"/>
            </material>
        </visual>

        <inertial>
            <origin xyz="0 0 .03" rpy="0 0 0"/>
            <mass value=".8" /> <inertia ixx=".001" ixy="0" ixz="0" iyy=".001" iyz="0" izz=".001" />
        </inertial>

        <collision>
            <geometry>
                <cylinder length=".06" radius="0.039"/>
            </geometry>
            <origin xyz="0 0 .029" rpy="0 0 0" />
        </collision>
    </link>

    <link name="link_2">
        <visual>
            <geometry>
                <cylinder length=".34" radius="0.005"/> </geometry>
            <origin xyz="0 0.17 0" rpy="1.57 0 0" /> <material name='blue'>
                <color rgba="0 0 0.8 1"/>
            </material>
        </visual>
        
        <inertial>
            <origin xyz="0 .17 0" rpy="0 0 0"/>
            <mass value="1.5" />
            <inertia ixx=".001" ixy="0" ixz="0" iyy=".001" iyz="0" izz=".001" />
        </inertial>

        <collision>
            <geometry>
                <cylinder length=".34" radius="0.005"/>
            </geometry>
            <origin xyz="0 .17 0" rpy="0 0 0" />
        </collision>
    </link>

    <link name="link_2_mimic">
        <visual>
            <geometry>
                <cylinder length=".34" radius="0.005"/>
            </geometry>
            <origin xyz="0 .17 0" rpy="1.57 0 0" />
            <material name='yellow'>
                <color rgba="0.9 .9 0 1"/>
            </material>
        </visual>
        
        <inertial>
            <origin xyz="0 .17 0" rpy="0 0 0"/>
            <mass value="1.5" />
            <inertia ixx=".001" ixy="0" ixz="0" iyy=".001" iyz="0" izz=".001" />
        </inertial>

        <collision>
            <geometry>
                <cylinder length=".34" radius="0.005"/>
            </geometry>
            <origin xyz="0 0.17 0" rpy="0 0 0" />
        </collision>
    </link>

    <link name="link_f2"> 
        <visual>
            <geometry>
                <cylinder length=".07" radius="0.03"/>
            </geometry>
            <origin xyz="0 .035 0" rpy="1.57 0 0" />
            <material name='black'>
                <color rgba="0 0 0 1"/>
            </material>
        </visual>
        
        <inertial>
            <origin xyz="0 .035 0" rpy="0 0 0"/>
            <mass value=".8" />
            <inertia ixx=".001" ixy="0" ixz="0" iyy=".001" iyz="0" izz=".001" />
        </inertial>

        <collision>
            <geometry>
                <cylinder length=".07" radius="0.03"/>
            </geometry>
            <origin xyz="0 0.035 0" rpy="0 0 0" />
        </collision>
    </link>

    <link name="link_pitch">
        <visual>
            <geometry>
                <cylinder length=".051" radius="0.0196"/>
            </geometry>
            <origin xyz="0 .0255 0" rpy="1.57 0 0" />
        </visual>

        <inertial>
            <origin xyz="0 0 .0255" rpy="0 0 0"/>
            <mass value=".2" />
            <inertia ixx=".001" ixy="0" ixz="0" iyy=".001" iyz="0" izz=".001" />
        </inertial>

        <collision>
            <geometry>
                <cylinder length=".051" radius="0.0196"/>
            </geometry>
            <origin xyz="0 0 .0255" rpy="0 0 0" />
        </collision>
    </link>
    
    <link name="link_yaw">
        <visual>
            <geometry>
                <cylinder length=".02475" radius="0.01996"/>
            </geometry>
            <origin xyz="0 0 0" rpy="0 0 0" />
            <material name='blue'>
                <color rgba="0 0 0.8 1"/>
            </material>
        </visual>

        <inertial>
            <origin xyz="0 0 .0124" rpy="0 0 0"/>
            <mass value=".2" />
            <inertia ixx=".001" ixy="0" ixz="0" iyy=".001" iyz="0" izz=".001" />
        </inertial>

        <collision>
            <geometry>
                <cylinder length=".02475" radius="0.01996"/>
            </geometry>
            <origin xyz="0 0 .0124" rpy="0 0 0" />
        </collision>
    </link>

    <link name="link_roll">
        <visual>
            <geometry>
                <box size="0.04588 0.04588 0.007"/>
            </geometry>
            <origin xyz="0 0 .0015" rpy="1.57 0 0" />
        </visual>

        <inertial>
            <origin xyz="0 0 .0015" rpy="0 0 0"/>
            <mass value=".2" />
            <inertia ixx=".001" ixy="0" ixz="0" iyy=".001" iyz="0" izz=".001" />
        </inertial>

        <collision>
            <geometry>
                <box size="0.04588 0.04588 0.007"/>
            </geometry>
            <origin xyz="0 0 .0015" rpy="0 0 0" />
        </collision>
    </link>

    <link name="link_camera">
        <visual>
            <geometry>
                <cylinder length=".005" radius="0.02"/>
            </geometry>
            <origin xyz="0 0 .001" rpy="1.57 0 0" />
            <material name='green'>
                <color rgba="0 0.8 0 1"/>
            </material>
        </visual>
        
        <inertial>
            <origin xyz="0 0 .001" rpy="0 0 0"/>
            <mass value=".2" />
            <inertia ixx=".001" ixy="0" ixz="0" iyy=".001" iyz="0" izz=".001" />
        </inertial>

        <collision>
            <geometry>
                <cylinder length=".02" radius="0.02"/>
            </geometry>
            <origin xyz="0 0 .001" rpy="0 0 0" />
        </collision>
    </link>

    <!-- Robot Joints -->
    <joint name="joint_base_rot" type="revolute">
        <parent link="base"/>
        <child link="link_rot"/>
        <origin xyz="0 0 .07" rpy="0 0 0" />
        <axis xyz="0 0 1" />
        <limit effort="1000.0" lower="-1.57" upper="1.57" velocity="1000"/>
    </joint>
  
    <joint name="joint_rot_1" type="revolute">
        <parent link="link_rot"/>
        <child link="link_1"/>
        <origin xyz="0 0.012 .041" rpy="0 0 0" />
        <axis xyz="1 0 0" />
        <limit effort="1000.0" lower="-.3927" upper="0.3927" velocity="1000"/>
    </joint>

    <joint name="joint_rot_1_mimic" type="revolute">
        <parent link="link_rot"/>
        <child link="link_1_mimic"/>
        <origin xyz="0 -0.012 .07" rpy="0 0 0" />
        <axis xyz="1 0 0" />
        <limit effort="1000.0" lower="-.3927" upper="0.3927" velocity="1000"/>
        <mimic joint="joint_rot_1" multiplier="1" offset="0"/>
    </joint>

    <joint name="joint_1_f1" type="continuous">
        <parent link="link_1"/>
        <child link="link_f1"/>
        <origin xyz="0 0 .336" rpy="-0.5470 0 0" />
        <axis xyz="1 0 0" />
        <mimic joint="joint_rot_1" multiplier="-1" offset="0"/>
    </joint>

    <joint name="joint_f1_2" type="revolute">
        <parent link="link_f1"/>
        <child link="link_2"/>
        <origin xyz="0 0 0.0374" rpy="0 0 0" />
        <axis xyz="1 0 0" />
        <limit effort="1000.0" lower="-.3927" upper=".3927" velocity="1000"/>
    </joint>

    <joint name="joint_f1_2_mimic" type="continuous">
        <parent link="link_f1"/>
        <child link="link_2_mimic"/>
        <origin xyz="0 0.02 0.0174" rpy="0 0 0" />
        <axis xyz="1 0 0" />
        <mimic joint="joint_f1_2" multiplier="1" offset="0"/>
    </joint>

    <joint name="joint_2_f2" type="continuous">
        <parent link="link_2"/>
        <child link="link_f2"/>
        <origin xyz="0 0.34 0" rpy="0 0 0" />
        <axis xyz="1 0 0" />
        <mimic joint="joint_f1_2" multiplier="-1" offset="0"/>
    </joint>

    <joint name="joint_f2_pitch" type="revolute">
        <parent link="link_f2"/>
        <child link="link_pitch"/>
        <origin xyz="0 0.0464 0" rpy="0 0 0" />
        <axis xyz="1 0 0" />
        <limit effort="1000.0" lower="-1.57" upper="1.57" velocity="1000"/>
    </joint>

    <joint name="joint_pitch_yaw" type="revolute">
        <parent link="link_pitch"/>
        <child link="link_yaw"/>
        <origin xyz="0 0.039 0.013" rpy="0 0 0" />
        <axis xyz="0 0 1" />
        <limit effort="1000.0" lower="-1.57" upper="1.57" velocity="1000"/>
    </joint>

    <joint name="joint_yaw_roll" type="revolute">
        <parent link="link_yaw"/>
        <child link="link_roll"/>
        <origin xyz="0.005 0.023 0.016" rpy="0 0 0" />
        <axis xyz="0 1 0" />
        <limit effort="1000.0" lower="-1.57" upper="1.57" velocity="1000"/>
    </joint>

    <joint name="joint_roll_camera" type="fixed">
        <parent link="link_roll"/>
        <child link="link_camera"/>
        <origin xyz="0 0.0177 0.0063" rpy="0 0 0" />
    </joint>

</robot>
